<?xml version='1.0'?>

<robot name="slam_bot" xmlns:xacro="http://www.ros.org/wiki/xacro">

  <xacro:include filename="$(find slam_project)/urdf/slam_bot.gazebo" />



  <link name="robot_footprint"></link>

  <joint name="robot_footprint_joint" type="fixed">
    <origin xyz="0 0 0" rpy="0 0 0" />
    <parent link="robot_footprint"/>
    <child link="chassis" />
  </joint>

  <link name='chassis'>
    <pose>0 0 0.1 0 0 0</pose>

    <inertial>
      <mass value="30.0"/>
      <origin xyz="0 0 0" rpy=" 0 0 0"/>
      <inertia
          ixx="1.29" ixy="0" ixz="0"
          iyy="2.3" iyz="0"
          izz="2.3"
      />
    </inertial>

    <collision name='collision'>
      <origin xyz="0 0 0" rpy=" 0 0 0"/> 
      <geometry>
        <box size=".8128 .508 .508"/>
      </geometry>
    </collision>

    <visual name='chassis_visual'>
      <origin xyz="0 0 0" rpy=" 0 0 0"/>
      <geometry>
        <box size=".8128 .508 .508"/>
      </geometry>
    </visual>


    <collision name='back_caster_collision'>
      <origin xyz="-0.3 0 -0.254" rpy=" 0 0 0"/>
      <geometry>
        <sphere radius="0.1709"/>
      </geometry>
      <surface>
        <friction>
          <ode>
            <mu>0</mu>
            <mu2>0</mu2>
            <slip1>1.0</slip1>
            <slip2>1.0</slip2>
          </ode>
        </friction>
      </surface>
    </collision>

    <visual name='back_caster_visual'>
      <origin xyz="-0.3 0 -0.254" rpy=" 0 0 0"/>
      <geometry>
        <sphere radius="0.171"/>
      </geometry>
    </visual>

  </link>




  <link name="left_wheel">

    <inertial>
      <mass value="5.0"/>
      <origin xyz="0 0 0" rpy="0 1.5707 1.5707"/>
      <!-- <inertia
          ixx="0.0779" ixy="0" ixz="0"
          iyy="0.0779" iyz="0"
          izz="0.146"
      />
      -->
      <inertia
          ixx="0.1" ixy="0" ixz="0"
          iyy="0.1" iyz="0"
          izz="0.1"
      />
    </inertial>

    <collision name='left_wheel_collision'>
      <origin xyz=" 0 0 0" rpy=" 0 1.5707 1.5707"/>
      <geometry>
        <cylinder radius="0.171" length="0.076"/>
      </geometry>
      <surface>
        <friction>
          <ode>
            <mu>0</mu>
            <mu2>0</mu2>
            <slip1>0.01</slip1>
            <slip2>0.01</slip2>
          </ode>
        </friction>
      </surface>
    </collision>

    <visual name='left_wheel_visual'>
      <origin xyz=" 0 0 0" rpy=" 0 1.5707 1.5707"/>
      <geometry>
        <cylinder radius="0.171" length="0.076"/>
      </geometry>
    </visual>
  </link>

  <joint type="continuous" name="left_wheel_hinge">
    <origin xyz="0.1524 0.304 -0.254" rpy="0 0 0"/>
    <child link="left_wheel"/>
    <parent link="chassis"/>
    <axis xyz="0 1 0" rpy="0 0 0"/>
    <limit effort="10000" velocity="1000"/>
    <joint_properties damping="1.0" friction="1.0"/>
  </joint>




  <link name="right_wheel">

    <inertial>
      <mass value="5.0"/>
      <origin xyz="0 0 0" rpy="0 1.5707 1.5707"/>
      <!-- <inertia
          ixx="0.0779" ixy="0" ixz="0"
          iyy="0.0779" iyz="0"
          izz="0.146"
      />
      -->
      <inertia
          ixx="0.1" ixy="0" ixz="0"
          iyy="0.1" iyz="0"
          izz="0.1"
      />
    </inertial>

    <collision name='right_wheel_collision'>
      <origin xyz="0 0 0" rpy="0 1.5707 1.5707"/>
      <geometry>
        <cylinder radius="0.171" length="0.076"/>
      </geometry>
      <surface>
        <friction>
          <ode>
            <mu>0</mu>
            <mu2>0</mu2>
            <slip1>0.01</slip1>
            <slip2>0.01</slip2>
          </ode>
        </friction>
      </surface>
    </collision>

    <visual name='right_wheel_visual'>
      <origin xyz="0 0 0" rpy="0 1.5707 1.5707"/>
      <geometry>
        <cylinder radius="0.171" length="0.076"/>
      </geometry>
    </visual>
  </link>

  <joint type="continuous" name="right_wheel_hinge">
    <origin xyz="0.1524 -0.304 -0.254" rpy="0 0 0"/>
    <child link="right_wheel"/>
    <parent link="chassis"/>
    <axis xyz="0 1 0" rpy="0 0 0"/>
    <limit effort="10000" velocity="1000"/>
    <joint_properties damping="1.0" friction="1.0"/>
  </joint>

  <link name="camera_link">

    <inertial>
      <mass value="0.1"/>
      <origin xyz=" 0 0 0" rpy=" 0 0 0"/>
      <inertia
          ixx="1e-6" ixy="0" ixz="0"
          iyy="1e-6" iyz="0"
          izz="1e-6"
      />
    </inertial>

    <collision name='camera_collision'>
      <origin xyz=" 0 0 0" rpy=" 0 0 0"/>
      <geometry>
        <box size="0.05 0.05 0.05"/>
      </geometry>
    </collision>

    <visual name='camera_visual'>
      <origin xyz=" 0 0 0" rpy=" 0 0 0"/>
      <geometry>
        <box size="0.05 0.05 0.05"/>
      </geometry>
    </visual>
  </link>

  <joint type="fixed" name="camera_joint">
    <origin xyz="0.4064 0 0" rpy="0 0 0"/>
    <child link="camera_link"/>
    <parent link="chassis"/>
  </joint>


  <link name="hokuyo">

    <inertial>
      <mass value="0.1"/>
      <origin xyz=" 0 0 0" rpy=" 0 0 0"/>
      <inertia
          ixx="1e-6" ixy="0" ixz="0"
          iyy="1e-6" iyz="0"
          izz="1e-6"
      />
    </inertial>

    <collision name='hokuyo_collision'>
      <origin xyz=" 0 0 0" rpy=" 0 0 0"/>
      <geometry>
        <box size="0.1 0.1 0.1"/>
      </geometry>
    </collision>

    <visual name='hokuyo_visual'>
      <origin xyz=" 0 0 0" rpy=" 0 0 0"/>
      <geometry>
        <mesh filename="package://slam_project/meshes/hokuyo.dae"/>
      </geometry>
    </visual>
  </link>

  <joint type="fixed" name="hokuyo_joint">
    <origin xyz="0.1524 0.0 0.29" rpy="0 0 0"/>
    <child link="hokuyo"/>
    <parent link="chassis"/>
  </joint>







</robot>
